{"ast":null,"code":"\"use strict\";\n\nvar __extends = this && this.__extends || function (d, b) {\n  for (var p in b) if (b.hasOwnProperty(p)) d[p] = b[p];\n\n  function __() {\n    this.constructor = d;\n  }\n\n  d.prototype = b === null ? Object.create(b) : (__.prototype = b.prototype, new __());\n};\n\nvar OuterSubscriber_1 = require('../OuterSubscriber');\n\nvar subscribeToResult_1 = require('../util/subscribeToResult');\n/**\n * Catches errors on the observable to be handled by returning a new observable or throwing an error.\n *\n * <img src=\"./img/catch.png\" width=\"100%\">\n *\n * @example <caption>Continues with a different Observable when there's an error</caption>\n *\n * Observable.of(1, 2, 3, 4, 5)\n *   .map(n => {\n * \t   if (n == 4) {\n * \t     throw 'four!';\n *     }\n *\t   return n;\n *   })\n *   .catch(err => Observable.of('I', 'II', 'III', 'IV', 'V'))\n *   .subscribe(x => console.log(x));\n *   // 1, 2, 3, I, II, III, IV, V\n *\n * @example <caption>Retries the caught source Observable again in case of error, similar to retry() operator</caption>\n *\n * Observable.of(1, 2, 3, 4, 5)\n *   .map(n => {\n * \t   if (n === 4) {\n * \t     throw 'four!';\n *     }\n * \t   return n;\n *   })\n *   .catch((err, caught) => caught)\n *   .take(30)\n *   .subscribe(x => console.log(x));\n *   // 1, 2, 3, 1, 2, 3, ...\n *\n * @example <caption>Throws a new error when the source Observable throws an error</caption>\n *\n * Observable.of(1, 2, 3, 4, 5)\n *   .map(n => {\n *     if (n == 4) {\n *       throw 'four!';\n *     }\n *     return n;\n *   })\n *   .catch(err => {\n *     throw 'error in source. Details: ' + err;\n *   })\n *   .subscribe(\n *     x => console.log(x),\n *     err => console.log(err)\n *   );\n *   // 1, 2, 3, error in source. Details: four!\n *\n * @param {function} selector a function that takes as arguments `err`, which is the error, and `caught`, which\n *  is the source observable, in case you'd like to \"retry\" that observable by returning it again. Whatever observable\n *  is returned by the `selector` will be used to continue the observable chain.\n * @return {Observable} An observable that originates from either the source or the observable returned by the\n *  catch `selector` function.\n * @name catchError\n */\n\n\nfunction catchError(selector) {\n  return function catchErrorOperatorFunction(source) {\n    var operator = new CatchOperator(selector);\n    var caught = source.lift(operator);\n    return operator.caught = caught;\n  };\n}\n\nexports.catchError = catchError;\n\nvar CatchOperator = function () {\n  function CatchOperator(selector) {\n    this.selector = selector;\n  }\n\n  CatchOperator.prototype.call = function (subscriber, source) {\n    return source.subscribe(new CatchSubscriber(subscriber, this.selector, this.caught));\n  };\n\n  return CatchOperator;\n}();\n/**\n * We need this JSDoc comment for affecting ESDoc.\n * @ignore\n * @extends {Ignored}\n */\n\n\nvar CatchSubscriber = function (_super) {\n  __extends(CatchSubscriber, _super);\n\n  function CatchSubscriber(destination, selector, caught) {\n    _super.call(this, destination);\n\n    this.selector = selector;\n    this.caught = caught;\n  } // NOTE: overriding `error` instead of `_error` because we don't want\n  // to have this flag this subscriber as `isStopped`. We can mimic the\n  // behavior of the RetrySubscriber (from the `retry` operator), where\n  // we unsubscribe from our source chain, reset our Subscriber flags,\n  // then subscribe to the selector result.\n\n\n  CatchSubscriber.prototype.error = function (err) {\n    if (!this.isStopped) {\n      var result = void 0;\n\n      try {\n        result = this.selector(err, this.caught);\n      } catch (err2) {\n        _super.prototype.error.call(this, err2);\n\n        return;\n      }\n\n      this._unsubscribeAndRecycle();\n\n      this.add(subscribeToResult_1.subscribeToResult(this, result));\n    }\n  };\n\n  return CatchSubscriber;\n}(OuterSubscriber_1.OuterSubscriber); //# sourceMappingURL=catchError.js.map","map":{"version":3,"sources":["/Users/nguyenlong/ProjectCompany/2nMart/websiteclient-2nmart.vn/node_modules/ng5-slider/node_modules/rxjs/operators/catchError.js"],"names":["__extends","d","b","p","hasOwnProperty","__","constructor","prototype","Object","create","OuterSubscriber_1","require","subscribeToResult_1","catchError","selector","catchErrorOperatorFunction","source","operator","CatchOperator","caught","lift","exports","call","subscriber","subscribe","CatchSubscriber","_super","destination","error","err","isStopped","result","err2","_unsubscribeAndRecycle","add","subscribeToResult","OuterSubscriber"],"mappings":"AAAA;;AACA,IAAIA,SAAS,GAAI,QAAQ,KAAKA,SAAd,IAA4B,UAAUC,CAAV,EAAaC,CAAb,EAAgB;AACxD,OAAK,IAAIC,CAAT,IAAcD,CAAd,EAAiB,IAAIA,CAAC,CAACE,cAAF,CAAiBD,CAAjB,CAAJ,EAAyBF,CAAC,CAACE,CAAD,CAAD,GAAOD,CAAC,CAACC,CAAD,CAAR;;AAC1C,WAASE,EAAT,GAAc;AAAE,SAAKC,WAAL,GAAmBL,CAAnB;AAAuB;;AACvCA,EAAAA,CAAC,CAACM,SAAF,GAAcL,CAAC,KAAK,IAAN,GAAaM,MAAM,CAACC,MAAP,CAAcP,CAAd,CAAb,IAAiCG,EAAE,CAACE,SAAH,GAAeL,CAAC,CAACK,SAAjB,EAA4B,IAAIF,EAAJ,EAA7D,CAAd;AACH,CAJD;;AAKA,IAAIK,iBAAiB,GAAGC,OAAO,CAAC,oBAAD,CAA/B;;AACA,IAAIC,mBAAmB,GAAGD,OAAO,CAAC,2BAAD,CAAjC;AACA;AACA;AACA;AACA;AACA;AACA;AACA;AACA;AACA;AACA;AACA;AACA;AACA;AACA;AACA;AACA;AACA;AACA;AACA;AACA;AACA;AACA;AACA;AACA;AACA;AACA;AACA;AACA;AACA;AACA;AACA;AACA;AACA;AACA;AACA;AACA;AACA;AACA;AACA;AACA;AACA;AACA;AACA;AACA;AACA;AACA;AACA;AACA;AACA;AACA;AACA;AACA;AACA;AACA;AACA;AACA;AACA;;;AACA,SAASE,UAAT,CAAoBC,QAApB,EAA8B;AAC1B,SAAO,SAASC,0BAAT,CAAoCC,MAApC,EAA4C;AAC/C,QAAIC,QAAQ,GAAG,IAAIC,aAAJ,CAAkBJ,QAAlB,CAAf;AACA,QAAIK,MAAM,GAAGH,MAAM,CAACI,IAAP,CAAYH,QAAZ,CAAb;AACA,WAAQA,QAAQ,CAACE,MAAT,GAAkBA,MAA1B;AACH,GAJD;AAKH;;AACDE,OAAO,CAACR,UAAR,GAAqBA,UAArB;;AACA,IAAIK,aAAa,GAAI,YAAY;AAC7B,WAASA,aAAT,CAAuBJ,QAAvB,EAAiC;AAC7B,SAAKA,QAAL,GAAgBA,QAAhB;AACH;;AACDI,EAAAA,aAAa,CAACX,SAAd,CAAwBe,IAAxB,GAA+B,UAAUC,UAAV,EAAsBP,MAAtB,EAA8B;AACzD,WAAOA,MAAM,CAACQ,SAAP,CAAiB,IAAIC,eAAJ,CAAoBF,UAApB,EAAgC,KAAKT,QAArC,EAA+C,KAAKK,MAApD,CAAjB,CAAP;AACH,GAFD;;AAGA,SAAOD,aAAP;AACH,CARoB,EAArB;AASA;AACA;AACA;AACA;AACA;;;AACA,IAAIO,eAAe,GAAI,UAAUC,MAAV,EAAkB;AACrC1B,EAAAA,SAAS,CAACyB,eAAD,EAAkBC,MAAlB,CAAT;;AACA,WAASD,eAAT,CAAyBE,WAAzB,EAAsCb,QAAtC,EAAgDK,MAAhD,EAAwD;AACpDO,IAAAA,MAAM,CAACJ,IAAP,CAAY,IAAZ,EAAkBK,WAAlB;;AACA,SAAKb,QAAL,GAAgBA,QAAhB;AACA,SAAKK,MAAL,GAAcA,MAAd;AACH,GANoC,CAOrC;AACA;AACA;AACA;AACA;;;AACAM,EAAAA,eAAe,CAAClB,SAAhB,CAA0BqB,KAA1B,GAAkC,UAAUC,GAAV,EAAe;AAC7C,QAAI,CAAC,KAAKC,SAAV,EAAqB;AACjB,UAAIC,MAAM,GAAG,KAAK,CAAlB;;AACA,UAAI;AACAA,QAAAA,MAAM,GAAG,KAAKjB,QAAL,CAAce,GAAd,EAAmB,KAAKV,MAAxB,CAAT;AACH,OAFD,CAGA,OAAOa,IAAP,EAAa;AACTN,QAAAA,MAAM,CAACnB,SAAP,CAAiBqB,KAAjB,CAAuBN,IAAvB,CAA4B,IAA5B,EAAkCU,IAAlC;;AACA;AACH;;AACD,WAAKC,sBAAL;;AACA,WAAKC,GAAL,CAAStB,mBAAmB,CAACuB,iBAApB,CAAsC,IAAtC,EAA4CJ,MAA5C,CAAT;AACH;AACJ,GAbD;;AAcA,SAAON,eAAP;AACH,CA3BsB,CA2BrBf,iBAAiB,CAAC0B,eA3BG,CAAvB,C,CA4BA","sourcesContent":["\"use strict\";\nvar __extends = (this && this.__extends) || function (d, b) {\n    for (var p in b) if (b.hasOwnProperty(p)) d[p] = b[p];\n    function __() { this.constructor = d; }\n    d.prototype = b === null ? Object.create(b) : (__.prototype = b.prototype, new __());\n};\nvar OuterSubscriber_1 = require('../OuterSubscriber');\nvar subscribeToResult_1 = require('../util/subscribeToResult');\n/**\n * Catches errors on the observable to be handled by returning a new observable or throwing an error.\n *\n * <img src=\"./img/catch.png\" width=\"100%\">\n *\n * @example <caption>Continues with a different Observable when there's an error</caption>\n *\n * Observable.of(1, 2, 3, 4, 5)\n *   .map(n => {\n * \t   if (n == 4) {\n * \t     throw 'four!';\n *     }\n *\t   return n;\n *   })\n *   .catch(err => Observable.of('I', 'II', 'III', 'IV', 'V'))\n *   .subscribe(x => console.log(x));\n *   // 1, 2, 3, I, II, III, IV, V\n *\n * @example <caption>Retries the caught source Observable again in case of error, similar to retry() operator</caption>\n *\n * Observable.of(1, 2, 3, 4, 5)\n *   .map(n => {\n * \t   if (n === 4) {\n * \t     throw 'four!';\n *     }\n * \t   return n;\n *   })\n *   .catch((err, caught) => caught)\n *   .take(30)\n *   .subscribe(x => console.log(x));\n *   // 1, 2, 3, 1, 2, 3, ...\n *\n * @example <caption>Throws a new error when the source Observable throws an error</caption>\n *\n * Observable.of(1, 2, 3, 4, 5)\n *   .map(n => {\n *     if (n == 4) {\n *       throw 'four!';\n *     }\n *     return n;\n *   })\n *   .catch(err => {\n *     throw 'error in source. Details: ' + err;\n *   })\n *   .subscribe(\n *     x => console.log(x),\n *     err => console.log(err)\n *   );\n *   // 1, 2, 3, error in source. Details: four!\n *\n * @param {function} selector a function that takes as arguments `err`, which is the error, and `caught`, which\n *  is the source observable, in case you'd like to \"retry\" that observable by returning it again. Whatever observable\n *  is returned by the `selector` will be used to continue the observable chain.\n * @return {Observable} An observable that originates from either the source or the observable returned by the\n *  catch `selector` function.\n * @name catchError\n */\nfunction catchError(selector) {\n    return function catchErrorOperatorFunction(source) {\n        var operator = new CatchOperator(selector);\n        var caught = source.lift(operator);\n        return (operator.caught = caught);\n    };\n}\nexports.catchError = catchError;\nvar CatchOperator = (function () {\n    function CatchOperator(selector) {\n        this.selector = selector;\n    }\n    CatchOperator.prototype.call = function (subscriber, source) {\n        return source.subscribe(new CatchSubscriber(subscriber, this.selector, this.caught));\n    };\n    return CatchOperator;\n}());\n/**\n * We need this JSDoc comment for affecting ESDoc.\n * @ignore\n * @extends {Ignored}\n */\nvar CatchSubscriber = (function (_super) {\n    __extends(CatchSubscriber, _super);\n    function CatchSubscriber(destination, selector, caught) {\n        _super.call(this, destination);\n        this.selector = selector;\n        this.caught = caught;\n    }\n    // NOTE: overriding `error` instead of `_error` because we don't want\n    // to have this flag this subscriber as `isStopped`. We can mimic the\n    // behavior of the RetrySubscriber (from the `retry` operator), where\n    // we unsubscribe from our source chain, reset our Subscriber flags,\n    // then subscribe to the selector result.\n    CatchSubscriber.prototype.error = function (err) {\n        if (!this.isStopped) {\n            var result = void 0;\n            try {\n                result = this.selector(err, this.caught);\n            }\n            catch (err2) {\n                _super.prototype.error.call(this, err2);\n                return;\n            }\n            this._unsubscribeAndRecycle();\n            this.add(subscribeToResult_1.subscribeToResult(this, result));\n        }\n    };\n    return CatchSubscriber;\n}(OuterSubscriber_1.OuterSubscriber));\n//# sourceMappingURL=catchError.js.map"]},"metadata":{},"sourceType":"script"}